Workbook

Sheet TỔNG QUAN & LƯU Ý
A1: P2+ - MÔ HÌNH ĐÁNH GIÁ NĂNG LỰC MỞ RỘNG
A3: P2+ là mô hình đánh giá năng lực mở rộng, trong đó kết quả thực hiện OKR/KPI được tích hợp như một thành phần của P2, thay vì tách thành P3 độc lập. Mục tiêu là đơn giản hóa quy trình, phản ánh đúng đặc thù công việc kỹ thuật và đảm bảo đánh giá cân bằng giữa năng lực dài hạn và kết quả ngắn hạn.
A5: 👉 Lưu ý quan trọng:
A6: • Đây không phải "bỏ P3" • Mà là biến thể có chủ đích, tích hợp OKR/KPI vào P2 • Giúp đánh giá toàn diện cả năng lực dài hạn (P2-Core) và kết quả ngắn hạn (P2-Delivery)

Sheet CẤU TRÚC & TRỌNG SỐ
A1: CẤU TRÚC & TRỌNG SỐ P2+
A3: I. CẤU TRÚC TỔNG THỂ P2+
A4: P2+ gồm 2 thành phần:
A5: A. P2-Core – Năng lực & cách làm việc
B6: • A. Năng lực kỹ thuật
B7: • B. Ownership & Trách nhiệm
B8: • C. DevOps & Vận hành
B9: • D. AI Agent & Cải tiến
A11: B. P2-Delivery – Kết quả công việc
B12: • OKR/KPI tháng hoặc quý
B13: • Chất lượng delivery
A16: II. CÁCH TÍNH ĐIỂM P2+
A17: P2+ là điểm đánh giá cuối cùng dùng để xếp loại năng lực.
A18: P2+ Tổng = (P2-Core × A) + (P2-Delivery × B)
A19: 📌 Trong đó:
A20: P2-Core: phản ánh năng lực & cách làm việc dài hạn
A21: P2-Delivery: phản ánh kết quả thực tế trong kỳ
A22: Trọng số A (Core) và B (Delivery): được điều chỉnh theo mục tiêu từng giai đoạn
A24: III. NGUYÊN TẮC ĐÁNH GIÁ (BẮT BUỘC TUÂN THỦ)
A25: 1️⃣ Không chấm trùng nội dung
B26: • P2-Core: chấm cách làm việc, năng lực, hành vi
B27: • P2-Delivery: chấm kết quả đầu ra
B28: • Ví dụ: Chủ động xử lý sự cố → P2-Core | Số lượng sự cố giảm → P2-Delivery
A30: 2️⃣ OKR không thay thế năng lực
B31: • Nhân sự có kết quả OKR cao nhưng vi phạm chuẩn kỹ thuật, gây rủi ro hệ thống hoặc ảnh hưởng đội nhóm sẽ không được xếp loại P2+ cao.
A33: 3️⃣ Đánh giá theo mặt bằng chung
B34: • Điểm số phản ánh mức độ ổn định và phổ biến
B35: • Không đánh giá theo 1–2 tình huống nổi bật
A37: IV. TRỌNG SỐ THEO VAI TRÒ
A38: Vai trò | B38: Năng lực kỹ thuật | C38: Ownership & trách nhiệm | D38: DevOps & vận hành | E38: AI Agent & cải tiến
A39: Design System | B39: 30 | C39: 25 | D39: 15 | E39: 30
A40: Backend | B40: 35 | C40: 25 | D40: 15 | E40: 25
A41: Frontend | B41: 30 | C41: 25 | D41: 10 | E41: 35
A42: Fullstack | B42: 30 | C42: 30 | D42: 15 | E42: 25
A44: V. NGƯỠNG XẾP LOẠI
A45: P2+ Tổng | B45: Xếp loại
A46: < 1 | B46: Chưa đạt
A47: 1 | B47: Đạt
A48: > 1 và ≤ 1.2 | B48: Tốt
A50: Level 2 Core | B50: Điểm
...

Sheet ĐÁNH GIÁ HIỆU SUẤT P2
A1: P2 PERFORMANCE EVALUATION
A3: Họ và tên | B3: NGUYỄN ĐĂNG ĐỨC | C3: Kỳ đánh giá | D3: Tháng 4
A4: Vai trò | B4: =IF(VLOOKUP(B3,'NHÂN SỰ'!A:B,2,0)=0,"",VLOOKUP(B3,'NHÂN SỰ'!A:B,2,0)) -> Frontend | C4: Người đánh giá
A6: NĂNG LỰC NỀN TẢNG (P2-Core – thang điểm từ 0.8 đến 1.0)
A7: Nhóm năng lực | B7: Trọng số (%) | C7: Mức hiện tại | D7: Điểm
A8: A. Năng lực kỹ thuật | B8: =IF(B4="",0,INDEX('CẤU TRÚC & TRỌNG SỐ'!B$39:B$42, MATCH(TRIM(B$4), 'CẤU TRÚC & TRỌNG SỐ'!A$39:A$42, 0))) -> 30 | C8: Đạt | D8: =IF(C8="","", B8*VLOOKUP(TRIM(UPPER(C8)), 'CẤU TRÚC & TRỌNG SỐ'!A$51:B$52, 2, FALSE())/100) -> 0.3
A9: B. Ownership & trách nhiệm | B9: =IF(B4="",0,INDEX('CẤU TRÚC & TRỌNG SỐ'!C$39:C$42, MATCH(TRIM(B$4), 'CẤU TRÚC & TRỌNG SỐ'!A$39:A$42, 0))) -> 25 | C9: Đạt | D9: =IF(C9="","", B9*VLOOKUP(TRIM(UPPER(C9)), 'CẤU TRÚC & TRỌNG SỐ'!A$51:B$52, 2, FALSE())/100) -> 0.25
A10: C. DevOps & vận hành (bắt buộc) | B10: =IF(B4="",0,INDEX('CẤU TRÚC & TRỌNG SỐ'!D$39:D$42, MATCH(TRIM(B$4), 'CẤU TRÚC & TRỌNG SỐ'!A$39:A$42, 0))) -> 10 | C10: Đạt | D10: =IF(C10="","", B10*VLOOKUP(TRIM(UPPER(C10)), 'CẤU TRÚC & TRỌNG SỐ'!A$51:B$52, 2, FALSE())/100) -> 0.1
A11: D. AI Agent & cải tiến (bắt buộc) | B11: =IF(B4="",0,INDEX('CẤU TRÚC & TRỌNG SỐ'!E$39:E$42, MATCH(TRIM(B$4), 'CẤU TRÚC & TRỌNG SỐ'!A$39:A$42, 0))) -> 35 | C11: Đạt | D11: =IF(C11="","", B11*VLOOKUP(TRIM(UPPER(C11)), 'CẤU TRÚC & TRỌNG SỐ'!A$51:B$52, 2, FALSE())/100) -> 0.35
A12: TỔNG | B12: =SUM(B8:B11) -> 100 | D12: =IF(OR(D8="", D9="", D10="", D11=""), "", SUM(D8:D11)) -> 1
A13: ĐÁNH GIÁ P2-CORE | D13: =IF(D12="","", IF(SUM(D8:D11)>0.8,"ĐẠT","CHƯA ĐẠT")) -> ĐẠT
A15: KẾT QUẢ CÔNG VIỆC (P2-Delivery – thang điểm từ 0.8 đến 1.2)
A16: Tiêu chí | B16: Mô tả | C16: MỨC ĐÁNH GIÁ
A17: Mức độ hoàn thành OKR | B17: Tỷ lệ hoàn thành các mục tiêu đã cam kết trong kỳ đánh giá | C17: Tốt
A18: Chất lượng kết quả | B18: Ít lỗi nghiêm trọng; hạn chế làm lại; không gây rủi ro hệ thống | C18: Đạt
A19: Cam kết & tiến độ | B19: Hoàn thành đúng hạn; chủ động báo sớm rủi ro; phối hợp tốt | C19: Tốt
A20: TỔNG ĐIỂM | C20: =IF(COUNTA(C17:C19)=0,"", IFERROR(VLOOKUP(C17,'CẤU TRÚC & TRỌNG SỐ'!A$55:B$57,2,0),0)*'CẤU TRÚC & TRỌNG SỐ'!B64 +IFERROR(VLOOKUP(C18,'CẤU TRÚC & TRỌNG SỐ'!A$55:B$57,2,0),0)*'CẤU TRÚC & TRỌNG SỐ'!B65 +IFERROR(VLOOKUP(C19,'CẤU TRÚC & TRỌNG SỐ'!A$55:B$57,2,0),0)*'CẤU TRÚC & TRỌNG SỐ'!B66) -> 1.13
A22: KẾT QUẢ HIỆU SUẤT P2
A23: TỔNG ĐIỂM | C23: =IF(OR(D12="",C20=""),"",D12*'CẤU TRÚC & TRỌNG SỐ'!B60+C20*'CẤU TRÚC & TRỌNG SỐ'!B61) -> 1.065
A24: ĐÁNH GIÁ TỔNG | C24: =IF(C23="","KHÔNG CÓ", IF(ROUND(C23,2)<1,"CHƯA ĐẠT", IF(ROUND(C23,2)=1,"ĐẠT","TỐT") ) ) -> TỐT
A26: THANG ĐÁNH GIÁ CHI TIẾT (Level 1/Level 2/Level 3)
A27: Mức | B27: Mô tả
A28: LEVEL 1 | B28: Thực hiện được các phần việc rõ ràng khi có hướng dẫn; cần review thường xuyên; chất lượng chưa ổn định.
A29: LEVEL 2 | B29: Tự triển khai độc lập; chất lượng ổn định, ít rework; chủ động xử lý rủi ro và cải thiện sản phẩm.
A30: LEVEL 3 | B30: Extra: Không chỉ hoàn thành tốt phần việc cá nhân mà còn cải tiến sản phẩm, chuẩn hoá cách làm và lan toả kinh nghiệm cho nhóm.

Sheet MÔ TẢ - PHỤ LỤC
A1: MÔ TẢ NĂNG LỰC THEO VAI TRÒ
A2: Gợi ý: dùng nút +/- (Outline) để thu gọn/mở rộng theo từng Vai trò. Cấp độ 1 (Thực thi – phối hợp): Làm tốt phần việc kỹ thuật của mình | Cấp độ 2 (Chủ động – cải tiến): Giải quyết bài toán xuyên hệ thống | Cấp độ 3 (Chuẩn hoá – dẫn dắt): Định hướng, tạo chuẩn, mở rộng
A4: Backend
A5: Nhóm năng lực | B5: Cấp độ 1 | C5: Cấp độ 2 | D5: Cấp độ 3
A6: A. Năng lực kỹ thuật | B6: Tự triển khai tính năng (API + DB); code dễ đọc; tests cơ bản; xử lý trường hợp lỗi không mong muốn xảy ra. | C6: Thiết kế kiến trúc/module gọn; cải thiện performance/security; tests chắc; nâng chất lượng qua review. | D6: Định hướng kiến trúc hệ thống có khả năng mở rộng; chủ động ngăn ngừa rủi ro và lỗi hệ thống; dẫn dắt cải tiến kỹ thuật lớn và hỗ trợ nâng cao năng lực đội ngũ.
A7: B. Ownership & trách nhiệm | B7: Bàn giao công việc ổn định; biết tách công việc thành các đầu việc rõ ràng; chịu trách nhiệm xử lý lỗi đến khi hoàn tất; chủ động báo sớm các rủi ro phát sinh. | C7: Chủ động quản lý phạm vi và rủi ro công việc; phối hợp hiệu quả với các bộ phận liên quan; giảm phát sinh làm lại nhờ yêu cầu và tài liệu được chuẩn bị rõ ràng. | D7: Cải tiến quy trình bàn giao công việc trong đội (tiêu chí hoàn thành, danh sách rà soát); xử lý các điểm nghẽn trong phối hợp giữa các nhóm; nâng cao khả năng dự báo và kiểm soát tiến độ chung.
A8: C. DevOps & vận hành | B8: Thực hiện quy trình tích hợp và triển khai tự động; hiểu và sử dụng đúng cấu hình môi trường, thông tin bảo mật; theo dõi nhật ký và lỗi hệ thống; tham gia trực xử lý sự cố khi cần. | C8: Chủ động cải thiện quy trình triển khai (tối ưu hiệu năng, kiểm soát chất lượng); bổ sung theo dõi chỉ số và cảnh báo; thực hiện phương án quay lui khi có sự cố; nâng cao độ ổn định và rút ngắn thời gian khắc phục lỗi. | D8: Chuẩn hóa quy trình phát hành và giám sát hệ thống; xây dựng hướng dẫn vận hành và xử lý sự cố; chủ trì phân tích nguyên nhân sau sự cố; hướng dẫn và nâng cao năng lực vận hành cho đội ngũ.
A9: D. AI Agent & cải tiến | B9: Sử dụng AI Agent để hỗ trợ code, chỉnh sửa code, viết kiểm thử và tìm lỗi; biết đặt yêu cầu rõ ràng; luôn kiểm tra lại kết quả trước khi áp dụng. | C9: Xây dựng mẫu yêu cầu và quy trình làm việc có thể tái sử dụng; dùng AI để hỗ trợ rà soát và tìm lỗi; theo dõi hiệu quả bằng các chỉ số như thời gian hoàn thành và tỷ lệ lỗi phát sinh. | D9: Dẫn dắt việc áp dụng AI trong kỹ thuật một cách có kiểm soát; đào tạo và hướng dẫn đội ngũ; tự động hóa các công việc lặp lại theo nguyên tắc an toàn, phân quyền và tuân thủ quy định nội bộ.
A11: Design System
A12: Nhóm năng lực | B12: Cấp độ 1 | C12: Cấp độ 2 | D12: Cấp độ 3
A13: A. Năng lực kỹ thuật | B13: Tự xây dựng luồng trải nghiệm và đặc tả giao diện; đảm bảo tính nhất quán về hình ảnh; bàn giao thiết kế rõ ràng để đội triển khai chính xác. | C13: Cải thiện khả năng sử dụng dựa trên nghiên cứu và đánh giá trải nghiệm; phát triển và mở rộng hệ thống thiết kế; giảm phát sinh làm lại nhờ đặc tả thiết kế rõ ràng. | D13: Định hướng thiết kế tổng thể; tạo ra tác động trải nghiệm người dùng có thể đo lường; quản trị và chuẩn hóa hệ thống thiết kế; hướng dẫn và kết nối các đội cùng áp dụng.
A14: B. Ownership & trách nhiệm | B14: Bàn giao công việc ổn định; xác định rõ phạm vi; lặp lại thiết kế kịp thời; phối hợp sớm với các bên triển khai để thống nhất ràng buộc. | C14: Quản lý các lựa chọn và đánh đổi trong thiết kế; chuẩn bị phương án thay thế; ghi nhận rõ các quyết định; giảm phát sinh làm lại thông qua rà soát thiết kế. | D14: Nâng chuẩn bàn giao thiết kế (tiêu chí hoàn thành, danh sách rà soát); tháo gỡ các vướng mắc phối hợp giữa các đội; nâng cao khả năng dự báo và kiểm soát tiến độ.
A15: C. DevOps & vận hành | B15: Làm việc với môi trường preview và staging; sử dụng nhất quán các thành phần và chuẩn thiết kế; xây dựng đặc tả phù hợp với khả năng triển khai. | C15: Thúc đẩy áp dụng chuẩn thành phần thiết kế; cải thiện tự động hóa bàn giao thiết kế–triển khai; giảm lỗi tích hợp và công việc làm lại. | D15: Dẫn dắt chuẩn hóa quy trình thiết kế–triển khai với đội phát triển; xây dựng hướng dẫn và các thực hành tốt cho toàn đội.
A16: D. AI Agent & cải tiến | B16: Sử dụng AI để hỗ trợ xây dựng khung thiết kế, nội dung trải nghiệm và phương án thiết kế; biết đặt yêu cầu phù hợp; kiểm tra và đối chiếu với hệ thống thiết kế hiện có. | C16: Xây dựng thư viện yêu cầu AI có thể tái sử dụng; tăng tốc tổng hợp nghiên cứu; theo dõi tác động của AI đến thời gian thực hiện và mức độ làm lại. | D16: Dẫn dắt việc áp dụng AI trong thiết kế một cách an toàn và có kiểm soát; đào tạo đội ngũ; tự động hóa các công việc lặp lại theo quy định và chuẩn quản trị.
A18: FrontEnd
A19: Nhóm năng lực | B19: Cấp độ 1 | C19: Cấp độ 2 | D19: Cấp độ 3
A20: A. Năng lực kỹ thuật | B20: Tự triển khai tính năng giao diện từ đầu đến cuối (giao diện, trạng thái, tích hợp dữ liệu); xử lý các tình huống phát sinh; viết mã rõ ràng, dễ bảo trì. | C20: Cải thiện hiệu năng và khả năng truy cập của giao diện; xây dựng thành phần dùng lại; nâng cao kiến trúc và kiểm thử để tăng độ ổn định. | D20: Định hướng kỹ thuật frontend; dẫn dắt các thay đổi lớn để giảm rủi ro; hướng dẫn đội ngũ; chủ động ngăn ngừa lỗi ảnh hưởng diện rộng trên giao diện.
A21: B. Ownership & trách nhiệm | B21: Bàn giao công việc ổn định; chịu trách nhiệm xử lý lỗi đến khi hoàn tất; phối hợp sớm với backend và thiết kế; chủ động báo rủi ro. | C21: Quản lý các lựa chọn và đánh đổi về trải nghiệm người dùng; giảm phát sinh làm lại; nâng chất lượng bàn giao bằng đặc tả, minh chứng và tài liệu rõ ràng. | D21: Nâng chuẩn bàn giao và rà soát (chuẩn thành phần, danh sách rà soát); tháo gỡ vướng mắc phối hợp giữa các đội; nâng cao khả năng dự báo và kiểm soát tiến độ.
A22: C. DevOps & vận hành | B22: Sử dụng thành thạo quy trình tích hợp và triển khai; quản lý cấu hình môi trường; theo dõi lỗi phía người dùng; giữ bản phát hành gọn và ổn định. | C22: Cải thiện quy trình triển khai (tối ưu tốc độ, kiểm soát chất lượng); giảm kích thước và thời gian tải; có phương án quay lui khi sự cố; nâng cao độ ổn định. | D22: Chuẩn hóa phát hành và giám sát cho frontend; xây dựng hướng dẫn xử lý sự cố; hướng dẫn đội ngũ thực hành vận hành; giảm lỗi phía người dùng và rút ngắn thời gian khắc phục.
A23: D. AI Agent & cải tiến | B23: Sử dụng AI để hỗ trợ tạo khung code, chỉnh sửa code, viết kiểm thử và tìm lỗi; biết đặt yêu cầu rõ ràng; luôn kiểm tra lại trước khi áp dụng. | C23: Xây dựng mẫu yêu cầu AI có thể tái sử dụng (thành phần, khả năng truy cập, kiểm thử); dùng AI hỗ trợ rà soát và cải tiến mã; theo dõi hiệu quả bằng các chỉ số phù hợp. | D23: Dẫn dắt việc áp dụng AI trong frontend theo quy chuẩn; đào tạo đội ngũ; tự động hóa các công việc lặp lại một cách an toàn và có kiểm soát.
A25: FullStack
A26: Nhóm năng lực | B26: Cấp độ 1 | C26: Cấp độ 2 | D26: Cấp độ 3 | E26: Cấp độ 4
A27: A. Năng lực kỹ thuật | B27: Tự triển khai tính năng từ đầu đến cuối (giao diện, xử lý dữ liệu, lưu trữ); đảm bảo chất lượng cơ bản; viết kiểm thử cần thiết; xử lý các tình huống lỗi phát sinh. | C27: Phân định rõ trách nhiệm giữa backend và frontend; cải thiện hiệu năng và an toàn hệ thống; thực hiện tái cấu trúc có kiểm soát; xây dựng kiểm thử vững chắc hơn. | D27: Định hướng kỹ thuật end-to-end; chủ động ngăn ngừa rủi ro và lỗi hệ thống; hướng dẫn đội ngũ; dẫn dắt các đợt tái cấu trúc và chuyển đổi hệ thống lớn một cách an toàn. | E27: Dẫn dắt định hướng kiến trúc ở cấp sản phẩm/hệ thống; xây dựng nền tảng kỹ thuật bền vững cho nhiều sản phẩm; tạo lợi thế công nghệ dài hạn và ảnh hưởng chiến lược đến tổ chức.
A28: B. Ownership & trách nhiệm | B28: Chịu trách nhiệm toàn bộ tính năng từ đầu đến cuối; đảm bảo vận hành ổn định; chủ động báo rủi ro; xử lý triệt để vấn đề đến khi hoàn tất. | C28: Quản lý phạm vi và rủi ro công việc; trao đổi và thống nhất các đánh đổi kỹ thuật; giảm phát sinh làm lại; cải thiện chất lượng tài liệu và bàn giao. | D28: Nâng cao khả năng dự báo; xây dựng và áp dụng các chuẩn chung (tiêu chí hoàn thành, danh sách rà soát); tháo gỡ vướng mắc trong phối hợp giữa các đội. | E28: Xây dựng hệ thống vận hành có khả năng tự kiểm soát; chủ động phòng ngừa rủi ro; mô hình quản lý trở thành chuẩn tham chiếu cho các đơn vị khác.
A29: C. DevOps & vận hành | B29: Sử dụng quy trình tích hợp và triển khai tự động; quản lý cấu hình và thông tin bảo mật; theo dõi lỗi và nhật ký hệ thống; triển khai an toàn và tham gia trực xử lý sự cố. | C29: Cải thiện quy trình triển khai; bổ sung theo dõi chỉ số và cảnh báo; có phương án quay lui khi cần; nâng cao độ ổn định trên toàn bộ hệ thống. | D29: Chuẩn hóa phát hành và giám sát hệ thống; xây dựng hướng dẫn vận hành và xử lý sự cố; giảm thời gian khắc phục lỗi; hướng dẫn đội ngũ thực hành vận hành hiệu quả. | E29: Định hướng chiến lược AI-first cho toàn bộ bộ phận; xây dựng môi trường phát triển tự động hoá cao (code/doc/test/deploy bằng AI); tối ưu chi phí nhân lực và tăng năng suất vượt trội cho tổ chức.
A30: D. AI Agent & cải tiến | B30: Sử dụng AI hỗ trợ toàn bộ chuỗi phát triển (tạo khung, chỉnh sửa code, kiểm thử, tìm lỗi); biết đặt yêu cầu phù hợp; luôn rà soát kỹ kết quả trước khi áp dụng. | C30: Xây dựng mẫu yêu cầu và quy trình làm việc với AI có thể tái sử dụng; dùng AI hỗ trợ rà soát và tìm lỗi; theo dõi tác động đến thời gian thực hiện và chất lượng. | D30: Dẫn dắt việc áp dụng AI trong phát triển end-to-end một cách an toàn và có kiểm soát; đào tạo đội ngũ; tự động hóa các công việc xuyên suốt theo chuẩn quản trị. | E30: Xây dựng đội ngũ tự chủ và kế thừa; phát triển năng lực tổng thể của bộ phận Công Nghệ; tạo văn hoá học tập, cải tiến liên tục và lan toả ảnh hưởng ra toàn công ty.

Sheet NHÂN SỰ
A1: NHÂN SỰ | B1: VAI TRÒ
A2: TRỊNH QUỐC HOÀN ĐẠT | B2: Fullstack
A3: BÙI VĂN HỔ | B3: Design System
A4: ĐINH TIẾN CHƯƠNG | B4: Frontend
A5: NGUYỄN ĐĂNG ĐỨC | B5: Frontend
A6: TRẦN CÔNG TUẤN ANH | B6: Frontend
A7: NGUYỄN HUY HOÀNG | B7: Backend

Sheet Summary_Ranking
A1: P2 SUMMARY & RANKING – BP CÔNG NGHỆ
A3: Nhập dữ liệu đánh giá của nhiều nhân sự để tự động xếp hạng. Cột 'Điểm P2' có thể nhập tay hoặc liên kết từ sheet role.
A5: STT | B5: Họ và tên | C5: Vai trò | D5: Kỳ đánh giá | E5: Điểm P2 | F5: Xếp loại | G5: Rank | H5: Ghi chú | I5: P2-Core | J5: OKR (P2-Delivery) | K5: P2+ Tổng | L5: P2-Core | M5: OKR (P2-Delivery) | N5: P2+ Tổng
A6: 1 | B6: Bùi Văn Hổ | C6: Designer, Frontend | F6: =IF(E6="","",IF(E6<2.5,"Chưa đạt",IF(E6<=3.2,"Đạt",IF(E6<=4,"Tốt","Rất tốt")))) | G6: =IF(E6="","",_xludf.rank.eq(E6,$E$6:$E$35,0)) | J6: ='đánh giá hiệu suất p2'!#ref! -> #VALUE! | K6: ='đánh giá hiệu suất p2'!#ref! -> #VALUE! | M6: ='đánh giá hiệu suất p2'!#ref! -> #VALUE! | N6: ='ĐÁNH GIÁ HIỆU SUẤT P2'!B20 -> 0
A7: 2 | B7: Nguyễn Huy Hoàng | C7: Backend, Frontend | F7: =IF(E7="","",IF(E7<2.5,"Chưa đạt",IF(E7<=3.2,"Đạt",IF(E7<=4,"Tốt","Rất tốt")))) | G7: =IF(E7="","",_xludf.rank.eq(E7,$E$6:$E$35,0)) | J7: ='đánh giá hiệu suất p2'!#ref! -> #VALUE! | K7: ='đánh giá hiệu suất p2'!#ref! -> #VALUE! | M7: ='đánh giá hiệu suất p2'!#ref! -> #VALUE! | N7: ='ĐÁNH GIÁ HIỆU SUẤT P2'!B20 -> 0
A8: 3 | B8: Đinh Tiến Chương | C8: Backend, Frontend | F8: =IF(E8="","",IF(E8<2.5,"Chưa đạt",IF(E8<=3.2,"Đạt",IF(E8<=4,"Tốt","Rất tốt")))) | G8: =IF(E8="","",_xludf.rank.eq(E8,$E$6:$E$35,0)) | J8: ='đánh giá hiệu suất p2'!#ref! -> #VALUE! | K8: ='đánh giá hiệu suất p2'!#ref! -> #VALUE! | M8: ='đánh giá hiệu suất p2'!#ref! -> #VALUE! | N8: ='ĐÁNH GIÁ HIỆU SUẤT P2'!B20 -> 0
A9: 4 | B9: Nguyễn Đăng Đức | C9: Backend, Frontend | F9: =IF(E9="","",IF(E9<2.5,"Chưa đạt",IF(E9<=3.2,"Đạt",IF(E9<=4,"Tốt","Rất tốt")))) | G9: =IF(E9="","",_xludf.rank.eq(E9,$E$6:$E$35,0)) | J9: ='đánh giá hiệu suất p2'!#ref! -> #VALUE! | K9: ='đánh giá hiệu suất p2'!#ref! -> #VALUE! | M9: ='đánh giá hiệu suất p2'!#ref! -> #VALUE! | N9: ='ĐÁNH GIÁ HIỆU SUẤT P2'!B20 -> 0
A10: 5 | F10: =IF(E10="","",IF(E10<2.5,"Chưa đạt",IF(E10<=3.2,"Đạt",IF(E10<=4,"Tốt","Rất tốt")))) | G10: =IF(E10="","",_xludf.rank.eq(E10,$E$6:$E$35,0)) | J10: ='đánh giá hiệu suất p2'!#ref! -> #VALUE! | K10: ='đánh giá hiệu suất p2'!#ref! -> #VALUE! | M10: ='đánh giá hiệu suất p2'!#ref! -> #VALUE! | N10: ='ĐÁNH GIÁ HIỆU SUẤT P2'!B20 -> 0
A11: 6 | F11: =IF(E11="","",IF(E11<2.5,"Chưa đạt",IF(E11<=3.2,"Đạt",IF(E11<=4,"Tốt","Rất tốt")))) | G11: =IF(E11="","",_xludf.rank.eq(E11,$E$6:$E$35,0)) | J11: ='đánh giá hiệu suất p2'!#ref! -> #VALUE! | K11: ='đánh giá hiệu suất p2'!#ref! -> #VALUE! | M11: ='đánh giá hiệu suất p2'!#ref! -> #VALUE! | N11: ='ĐÁNH GIÁ HIỆU SUẤT P2'!B20 -> 0
A12: 7 | F12: =IF(E12="","",IF(E12<2.5,"Chưa đạt",IF(E12<=3.2,"Đạt",IF(E12<=4,"Tốt","Rất tốt")))) | G12: =IF(E12="","",_xludf.rank.eq(E12,$E$6:$E$35,0)) | J12: ='đánh giá hiệu suất p2'!#ref! -> #VALUE! | K12: ='đánh giá hiệu suất p2'!#ref! -> #VALUE! | M12: ='đánh giá hiệu suất p2'!#ref! -> #VALUE! | N12: ='ĐÁNH GIÁ HIỆU SUẤT P2'!B20 -> 0
A13: 8 | F13: =IF(E13="","",IF(E13<2.5,"Chưa đạt",IF(E13<=3.2,"Đạt",IF(E13<=4,"Tốt","Rất tốt")))) | G13: =IF(E13="","",_xludf.rank.eq(E13,$E$6:$E$35,0)) | J13: ='đánh giá hiệu suất p2'!#ref! -> #VALUE! | K13: ='đánh giá hiệu suất p2'!#ref! -> #VALUE! | M13: ='đánh giá hiệu suất p2'!#ref! -> #VALUE! | N13: ='ĐÁNH GIÁ HIỆU SUẤT P2'!B20 -> 0
A14: 9 | F14: =IF(E14="","",IF(E14<2.5,"Chưa đạt",IF(E14<=3.2,"Đạt",IF(E14<=4,"Tốt","Rất tốt")))) | G14: =IF(E14="","",_xludf.rank.eq(E14,$E$6:$E$35,0)) | J14: ='đánh giá hiệu suất p2'!#ref! -> #VALUE! | K14: ='đánh giá hiệu suất p2'!#ref! -> #VALUE! | M14: ='đánh giá hiệu suất p2'!#ref! -> #VALUE! | N14: ='ĐÁNH GIÁ HIỆU SUẤT P2'!B20 -> 0
A15: 10 | F15: =IF(E15="","",IF(E15<2.5,"Chưa đạt",IF(E15<=3.2,"Đạt",IF(E15<=4,"Tốt","Rất tốt")))) | G15: =IF(E15="","",_xludf.rank.eq(E15,$E$6:$E$35,0)) | J15: ='đánh giá hiệu suất p2'!#ref! -> #VALUE! | K15: ='đánh giá hiệu suất p2'!#ref! -> #VALUE! | M15: ='đánh giá hiệu suất p2'!#ref! -> #VALUE! | N15: ='ĐÁNH GIÁ HIỆU SUẤT P2'!B20 -> 0
A16: 11 | F16: =IF(E16="","",IF(E16<2.5,"Chưa đạt",IF(E16<=3.2,"Đạt",IF(E16<=4,"Tốt","Rất tốt")))) | G16: =IF(E16="","",_xludf.rank.eq(E16,$E$6:$E$35,0)) | J16: ='đánh giá hiệu suất p2'!#ref! -> #VALUE! | K16: ='đánh giá hiệu suất p2'!#ref! -> #VALUE! | M16: ='đánh giá hiệu suất p2'!#ref! -> #VALUE! | N16: ='ĐÁNH GIÁ HIỆU SUẤT P2'!B20 -> 0
A17: 12 | F17: =IF(E17="","",IF(E17<2.5,"Chưa đạt",IF(E17<=3.2,"Đạt",IF(E17<=4,"Tốt","Rất tốt")))) | G17: =IF(E17="","",_xludf.rank.eq(E17,$E$6:$E$35,0)) | J17: ='đánh giá hiệu suất p2'!#ref! -> #VALUE! | K17: ='đánh giá hiệu suất p2'!#ref! -> #VALUE! | M17: ='đánh giá hiệu suất p2'!#ref! -> #VALUE! | N17: ='ĐÁNH GIÁ HIỆU SUẤT P2'!B20 -> 0
A18: 13 | F18: =IF(E18="","",IF(E18<2.5,"Chưa đạt",IF(E18<=3.2,"Đạt",IF(E18<=4,"Tốt","Rất tốt")))) | G18: =IF(E18="","",_xludf.rank.eq(E18,$E$6:$E$35,0)) | J18: ='đánh giá hiệu suất p2'!#ref! -> #VALUE! | K18: ='đánh giá hiệu suất p2'!#ref! -> #VALUE! | M18: ='đánh giá hiệu suất p2'!#ref! -> #VALUE! | N18: ='ĐÁNH GIÁ HIỆU SUẤT P2'!B20 -> 0
A19: 14 | F19: =IF(E19="","",IF(E19<2.5,"Chưa đạt",IF(E19<=3.2,"Đạt",IF(E19<=4,"Tốt","Rất tốt")))) | G19: =IF(E19="","",_xludf.rank.eq(E19,$E$6:$E$35,0)) | J19: ='đánh giá hiệu suất p2'!#ref! -> #VALUE! | K19: ='đánh giá hiệu suất p2'!#ref! -> #VALUE! | M19: ='đánh giá hiệu suất p2'!#ref! -> #VALUE! | N19: ='ĐÁNH GIÁ HIỆU SUẤT P2'!B20 -> 0
A20: 15 | F20: =IF(E20="","",IF(E20<2.5,"Chưa đạt",IF(E20<=3.2,"Đạt",IF(E20<=4,"Tốt","Rất tốt")))) | G20: =IF(E20="","",_xludf.rank.eq(E20,$E$6:$E$35,0)) | J20: ='đánh giá hiệu suất p2'!#ref! -> #VALUE! | K20: ='đánh giá hiệu suất p2'!#ref! -> #VALUE! | M20: ='đánh giá hiệu suất p2'!#ref! -> #VALUE! | N20: ='ĐÁNH GIÁ HIỆU SUẤT P2'!B20 -> 0
A21: 16 | F21: =IF(E21="","",IF(E21<2.5,"Chưa đạt",IF(E21<=3.2,"Đạt",IF(E21<=4,"Tốt","Rất tốt")))) | G21: =IF(E21="","",_xludf.rank.eq(E21,$E$6:$E$35,0)) | J21: ='đánh giá hiệu suất p2'!#ref! -> #VALUE! | K21: ='đánh giá hiệu suất p2'!#ref! -> #VALUE! | M21: ='đánh giá hiệu suất p2'!#ref! -> #VALUE! | N21: ='ĐÁNH GIÁ HIỆU SUẤT P2'!B20 -> 0
A22: 17 | F22: =IF(E22="","",IF(E22<2.5,"Chưa đạt",IF(E22<=3.2,"Đạt",IF(E22<=4,"Tốt","Rất tốt")))) | G22: =IF(E22="","",_xludf.rank.eq(E22,$E$6:$E$35,0)) | J22: ='đánh giá hiệu suất p2'!#ref! -> #VALUE! | K22: ='đánh giá hiệu suất p2'!#ref! -> #VALUE! | M22: ='đánh giá hiệu suất p2'!#ref! -> #VALUE! | N22: ='ĐÁNH GIÁ HIỆU SUẤT P2'!B20 -> 0
A23: 18 | F23: =IF(E23="","",IF(E23<2.5,"Chưa đạt",IF(E23<=3.2,"Đạt",IF(E23<=4,"Tốt","Rất tốt")))) | G23: =IF(E23="","",_xludf.rank.eq(E23,$E$6:$E$35,0)) | J23: ='đánh giá hiệu suất p2'!#ref! -> #VALUE! | K23: ='đánh giá hiệu suất p2'!#ref! -> #VALUE! | M23: ='đánh giá hiệu suất p2'!#ref! -> #VALUE! | N23: ='ĐÁNH GIÁ HIỆU SUẤT P2'!B20 -> 0
A24: 19 | F24: =IF(E24="","",IF(E24<2.5,"Chưa đạt",IF(E24<=3.2,"Đạt",IF(E24<=4,"Tốt","Rất tốt")))) | G24: =IF(E24="","",_xludf.rank.eq(E24,$E$6:$E$35,0)) | J24: ='đánh giá hiệu suất p2'!#ref! -> #VALUE! | K24: ='đánh giá hiệu suất p2'!#ref! -> #VALUE! | M24: ='đánh giá hiệu suất p2'!#ref! -> #VALUE! | N24: ='ĐÁNH GIÁ HIỆU SUẤT P2'!B20 -> 0
A25: 20 | F25: =IF(E25="","",IF(E25<2.5,"Chưa đạt",IF(E25<=3.2,"Đạt",IF(E25<=4,"Tốt","Rất tốt")))) | G25: =IF(E25="","",_xludf.rank.eq(E25,$E$6:$E$35,0)) | J25: ='đánh giá hiệu suất p2'!#ref! -> #VALUE! | K25: ='đánh giá hiệu suất p2'!#ref! -> #VALUE! | M25: ='đánh giá hiệu suất p2'!#ref! -> #VALUE! | N25: ='ĐÁNH GIÁ HIỆU SUẤT P2'!B20 -> 0
A26: 21 | F26: =IF(E26="","",IF(E26<2.5,"Chưa đạt",IF(E26<=3.2,"Đạt",IF(E26<=4,"Tốt","Rất tốt")))) | G26: =IF(E26="","",_xludf.rank.eq(E26,$E$6:$E$35,0)) | J26: ='đánh giá hiệu suất p2'!#ref! -> #VALUE! | K26: ='đánh giá hiệu suất p2'!#ref! -> #VALUE! | M26: ='đánh giá hiệu suất p2'!#ref! -> #VALUE! | N26: ='ĐÁNH GIÁ HIỆU SUẤT P2'!B20 -> 0
A27: 22 | F27: =IF(E27="","",IF(E27<2.5,"Chưa đạt",IF(E27<=3.2,"Đạt",IF(E27<=4,"Tốt","Rất tốt")))) | G27: =IF(E27="","",_xludf.rank.eq(E27,$E$6:$E$35,0)) | J27: ='đánh giá hiệu suất p2'!#ref! -> #VALUE! | K27: ='đánh giá hiệu suất p2'!#ref! -> #VALUE! | M27: ='đánh giá hiệu suất p2'!#ref! -> #VALUE! | N27: ='ĐÁNH GIÁ HIỆU SUẤT P2'!B20 -> 0
A28: 23 | F28: =IF(E28="","",IF(E28<2.5,"Chưa đạt",IF(E28<=3.2,"Đạt",IF(E28<=4,"Tốt","Rất tốt")))) | G28: =IF(E28="","",_xludf.rank.eq(E28,$E$6:$E$35,0)) | J28: ='đánh giá hiệu suất p2'!#ref! -> #VALUE! | K28: ='đánh giá hiệu suất p2'!#ref! -> #VALUE! | M28: ='đánh giá hiệu suất p2'!#ref! -> #VALUE! | N28: ='ĐÁNH GIÁ HIỆU SUẤT P2'!B20 -> 0
A29: 24 | F29: =IF(E29="","",IF(E29<2.5,"Chưa đạt",IF(E29<=3.2,"Đạt",IF(E29<=4,"Tốt","Rất tốt")))) | G29: =IF(E29="","",_xludf.rank.eq(E29,$E$6:$E$35,0)) | J29: ='đánh giá hiệu suất p2'!#ref! -> #VALUE! | K29: ='đánh giá hiệu suất p2'!#ref! -> #VALUE! | M29: ='đánh giá hiệu suất p2'!#ref! -> #VALUE! | N29: ='ĐÁNH GIÁ HIỆU SUẤT P2'!B20 -> 0
A30: 25 | F30: =IF(E30="","",IF(E30<2.5,"Chưa đạt",IF(E30<=3.2,"Đạt",IF(E30<=4,"Tốt","Rất tốt")))) | G30: =IF(E30="","",_xludf.rank.eq(E30,$E$6:$E$35,0)) | J30: ='đánh giá hiệu suất p2'!#ref! -> #VALUE! | K30: ='đánh giá hiệu suất p2'!#ref! -> #VALUE! | M30: ='đánh giá hiệu suất p2'!#ref! -> #VALUE! | N30: ='ĐÁNH GIÁ HIỆU SUẤT P2'!B20 -> 0
A31: 26 | F31: =IF(E31="","",IF(E31<2.5,"Chưa đạt",IF(E31<=3.2,"Đạt",IF(E31<=4,"Tốt","Rất tốt")))) | G31: =IF(E31="","",_xludf.rank.eq(E31,$E$6:$E$35,0)) | J31: ='đánh giá hiệu suất p2'!#ref! -> #VALUE! | K31: ='đánh giá hiệu suất p2'!#ref! -> #VALUE! | M31: ='đánh giá hiệu suất p2'!#ref! -> #VALUE! | N31: ='ĐÁNH GIÁ HIỆU SUẤT P2'!B20 -> 0
A32: 27 | F32: =IF(E32="","",IF(E32<2.5,"Chưa đạt",IF(E32<=3.2,"Đạt",IF(E32<=4,"Tốt","Rất tốt")))) | G32: =IF(E32="","",_xludf.rank.eq(E32,$E$6:$E$35,0)) | J32: ='đánh giá hiệu suất p2'!#ref! -> #VALUE! | K32: ='đánh giá hiệu suất p2'!#ref! -> #VALUE! | M32: ='đánh giá hiệu suất p2'!#ref! -> #VALUE! | N32: ='ĐÁNH GIÁ HIỆU SUẤT P2'!B20 -> 0
A33: 28 | F33: =IF(E33="","",IF(E33<2.5,"Chưa đạt",IF(E33<=3.2,"Đạt",IF(E33<=4,"Tốt","Rất tốt")))) | G33: =IF(E33="","",_xludf.rank.eq(E33,$E$6:$E$35,0)) | J33: ='đánh giá hiệu suất p2'!#ref! -> #VALUE! | K33: ='đánh giá hiệu suất p2'!#ref! -> #VALUE! | M33: ='đánh giá hiệu suất p2'!#ref! -> #VALUE! | N33: ='ĐÁNH GIÁ HIỆU SUẤT P2'!B20 -> 0
A34: 29 | F34: =IF(E34="","",IF(E34<2.5,"Chưa đạt",IF(E34<=3.2,"Đạt",IF(E34<=4,"Tốt","Rất tốt")))) | G34: =IF(E34="","",_xludf.rank.eq(E34,$E$6:$E$35,0)) | J34: ='đánh giá hiệu suất p2'!#ref! -> #VALUE! | K34: ='đánh giá hiệu suất p2'!#ref! -> #VALUE! | M34: ='đánh giá hiệu suất p2'!#ref! -> #VALUE! | N34: ='ĐÁNH GIÁ HIỆU SUẤT P2'!B20 -> 0
A35: 30 | F35: =IF(E35="","",IF(E35<2.5,"Chưa đạt",IF(E35<=3.2,"Đạt",IF(E35<=4,"Tốt","Rất tốt")))) | G35: =IF(E35="","",_xludf.rank.eq(E35,$E$6:$E$35,0)) | J35: ='đánh giá hiệu suất p2'!#ref! -> #VALUE! | K35: ='đánh giá hiệu suất p2'!#ref! -> #VALUE! | M35: ='đánh giá hiệu suất p2'!#ref! -> #VALUE! | N35: ='ĐÁNH GIÁ HIỆU SUẤT P2'!B20 -> 0
